Traceback (most recent call last):
  File "/home/ross/.virtualenvs/skimage-tutorials/lib/python3.10/site-packages/jupyter_cache/executors/utils.py", line 51, in single_nb_execution
    executenb(
  File "/home/ross/.virtualenvs/skimage-tutorials/lib/python3.10/site-packages/nbclient/client.py", line 1093, in execute
    return NotebookClient(nb=nb, resources=resources, km=km, **kwargs).execute()
  File "/home/ross/.virtualenvs/skimage-tutorials/lib/python3.10/site-packages/nbclient/util.py", line 84, in wrapped
    return just_run(coro(*args, **kwargs))
  File "/home/ross/.virtualenvs/skimage-tutorials/lib/python3.10/site-packages/nbclient/util.py", line 62, in just_run
    return loop.run_until_complete(coro)
  File "/usr/lib/python3.10/asyncio/base_events.py", line 641, in run_until_complete
    return future.result()
  File "/home/ross/.virtualenvs/skimage-tutorials/lib/python3.10/site-packages/nbclient/client.py", line 559, in async_execute
    await self.async_execute_cell(
  File "/home/ross/.virtualenvs/skimage-tutorials/lib/python3.10/site-packages/nbclient/client.py", line 854, in async_execute_cell
    self._check_raise_for_error(cell, exec_reply)
  File "/home/ross/.virtualenvs/skimage-tutorials/lib/python3.10/site-packages/nbclient/client.py", line 756, in _check_raise_for_error
    raise CellExecutionError.from_cell_and_msg(cell, exec_reply_content)
nbclient.exceptions.CellExecutionError: An error occurred while executing the following cell:
------------------
from keras import models, layers
from keras.layers import Conv2D, MaxPooling2D, UpSampling2D

M = 76
N = int(23 / 76 * M) * 2

model = models.Sequential()
model.add(
    Conv2D(
        32,
        kernel_size=(2, 2),
        activation='relu',
        input_shape=(N, N, 1),
        padding='same'
    )
)
model.add(MaxPooling2D(pool_size=(2, 2)))
model.add(Conv2D(64, (3, 3), activation='relu', padding='same'))
model.add(Conv2D(64, (3, 3), activation='relu', padding='same'))
model.add(UpSampling2D(size=(2, 2)))
model.add(
    Conv2D(
        1,
        kernel_size=(2, 2),
        activation='sigmoid',
        padding='same'
    )
)
model.compile(loss='mse', optimizer='Adam', metrics=['accuracy'])

# Load pre-trained weights from disk
model.load_weights('../data/keras_model-diatoms-pores.h5')
------------------

[0;31m---------------------------------------------------------------------------[0m
[0;31mModuleNotFoundError[0m                       Traceback (most recent call last)
Input [0;32mIn [23][0m, in [0;36m<module>[0;34m[0m
[0;32m----> 1[0m [38;5;28;01mfrom[39;00m [38;5;21;01mkeras[39;00m [38;5;28;01mimport[39;00m models, layers
[1;32m      2[0m [38;5;28;01mfrom[39;00m [38;5;21;01mkeras[39;00m[38;5;21;01m.[39;00m[38;5;21;01mlayers[39;00m [38;5;28;01mimport[39;00m Conv2D, MaxPooling2D, UpSampling2D
[1;32m      4[0m M [38;5;241m=[39m [38;5;241m76[39m

[0;31mModuleNotFoundError[0m: No module named 'keras'
ModuleNotFoundError: No module named 'keras'

