Traceback (most recent call last):
  File "/home/ross/.virtualenvs/skimage-tutorials/lib/python3.10/site-packages/jupyter_cache/executors/utils.py", line 51, in single_nb_execution
    executenb(
  File "/home/ross/.virtualenvs/skimage-tutorials/lib/python3.10/site-packages/nbclient/client.py", line 1093, in execute
    return NotebookClient(nb=nb, resources=resources, km=km, **kwargs).execute()
  File "/home/ross/.virtualenvs/skimage-tutorials/lib/python3.10/site-packages/nbclient/util.py", line 84, in wrapped
    return just_run(coro(*args, **kwargs))
  File "/home/ross/.virtualenvs/skimage-tutorials/lib/python3.10/site-packages/nbclient/util.py", line 62, in just_run
    return loop.run_until_complete(coro)
  File "/usr/lib/python3.10/asyncio/base_events.py", line 641, in run_until_complete
    return future.result()
  File "/home/ross/.virtualenvs/skimage-tutorials/lib/python3.10/site-packages/nbclient/client.py", line 559, in async_execute
    await self.async_execute_cell(
  File "/home/ross/.virtualenvs/skimage-tutorials/lib/python3.10/site-packages/nbclient/client.py", line 854, in async_execute_cell
    self._check_raise_for_error(cell, exec_reply)
  File "/home/ross/.virtualenvs/skimage-tutorials/lib/python3.10/site-packages/nbclient/client.py", line 756, in _check_raise_for_error
    raise CellExecutionError.from_cell_and_msg(cell, exec_reply_content)
nbclient.exceptions.CellExecutionError: An error occurred while executing the following cell:
------------------
import pandas as pd


info_table = pd.DataFrame(
    measure.regionprops_table(
        relabeled, nuclei,
        properties=['label', 'slice', 'area', 'mean_intensity', 'solidity'],
    )
).set_index('label')
------------------

[0;31m---------------------------------------------------------------------------[0m
[0;31mModuleNotFoundError[0m                       Traceback (most recent call last)
Input [0;32mIn [38][0m, in [0;36m<module>[0;34m[0m
[0;32m----> 1[0m [38;5;28;01mimport[39;00m [38;5;21;01mpandas[39;00m [38;5;28;01mas[39;00m [38;5;21;01mpd[39;00m
[1;32m      4[0m info_table [38;5;241m=[39m pd[38;5;241m.[39mDataFrame(
[1;32m      5[0m     measure[38;5;241m.[39mregionprops_table(
[1;32m      6[0m         relabeled, nuclei,
[1;32m      7[0m         properties[38;5;241m=[39m[[38;5;124m'[39m[38;5;124mlabel[39m[38;5;124m'[39m, [38;5;124m'[39m[38;5;124mslice[39m[38;5;124m'[39m, [38;5;124m'[39m[38;5;124marea[39m[38;5;124m'[39m, [38;5;124m'[39m[38;5;124mmean_intensity[39m[38;5;124m'[39m, [38;5;124m'[39m[38;5;124msolidity[39m[38;5;124m'[39m],
[1;32m      8[0m     )
[1;32m      9[0m )[38;5;241m.[39mset_index([38;5;124m'[39m[38;5;124mlabel[39m[38;5;124m'[39m)

[0;31mModuleNotFoundError[0m: No module named 'pandas'
ModuleNotFoundError: No module named 'pandas'

